Workbook
Name atc_size: #REF!

Sheet Target historical Info
A1: AIRTHREAD CONNECTIONS
A3: Historical Operating Results (all numbers excep figures at per share level are in millions)
A5: Income Statement
G6: Closing
A7: Operating Results: | E7: 2005 | F7: =E7+1 -> 2006 | G7: 2007
A8: Total Revenue | E8: 3030.765 | F8: 3473.155 | G8: 3946.264
A9: Less: System Operating Expenses | E9: 604.093 | F9: 639.683 | G9: 717.075
A10: Less: Cost of Goods Sold | E10: 511.939 | F10: 568.903 | G10: 640.225
A11: Less: Selling, General & Administrative | E11: 1217.709 | F11: 1399.561 | G11: 1555.639
A12: EBITDA | E12: =E8-SUM(E9:E11) -> 697.024 | F12: =F8-SUM(F9:F11) -> 865.008 | G12: =G8-SUM(G9:G11) -> 1033.325
A13: Less: Depreciation & Amortization | E13: 490.093 | F13: 555.525 | G13: 582.269
A14: EBIT | E14: =E12-E13 -> 206.931 | F14: =F12-F13 -> 309.483 | G14: =G12-G13 -> 451.056
A15: Less: Interest Expense | E15: 84.867 | F15: 93.674 | G15: 84.679
A16: Plus: Income from other non-operating assets | E16: 66.719 | F16: 93.119 | G16: 90.033
A17: Plus: Gains (Losses) on Investments | E17: 18.063 | F17: 50.84 | G17: 83.13
A18: Plus: Other Income | E18: 54.501 | F18: -46.63 | G18: 6.961
A19: EBT | E19: =E14-E15+E16+E17+E18 -> 261.347 | F19: =F14-F15+F16+F17+F18 -> 313.138 | G19: =G14-G15+G16+G17+G18 -> 546.501
A20: Less: Taxes | E20: 95.856 | F20: 120.604 | G20: 216.711
A21: Income Before Minority Interest | E21: =E19-E20 -> 165.491 | F21: =F19-F20 -> 192.534 | G21: =G19-G20 -> 329.79
A22: Less: Minority Interest | E22: 0 | F22: 0 | G22: 0
A23: Net Income | E23: =E21-E22 -> 165.491 | F23: =F21-F22 -> 192.534 | G23: =G21-G22 -> 329.79
A24: Number of shares outstanding | E24: 100 | F24: 100 | G24: 100
A25: EPS ($) | E25: =E23/E24 -> 1.65491 | F25: =F23/F24 -> 1.92534 | G25: =G23/G24 -> 3.2979
A30: Balance Sheets
G31: Closing
A32: Assets | E32: 2005 | F32: 2006 | G32: 2007
A33: Cash & Cash Equivalents | E33: 29.003 | F33: 281.951 | G33: 220.885
A34: Accounts Receivable | E34: 362.359 | F34: 407.438 | G34: 435.497
A35: Inventory | E35: 92.748 | F35: 117.189 | G35: 100.99
A36: Other Current Assets | E36: 55.775 | F36: 48.34 | G36: 76.381
A37: Current Assets | E37: =SUM(E33:E36) -> 539.885 | F37: =SUM(F33:F36) -> 854.918 | G37: =SUM(G33:G36) -> 833.753
A38: Property, Plan & Equipment | E38: 2553.029 | F38: 2628.848 | G38: 2595.096
A39: Intangible assets | E39: 1409.912 | F39: 1520.523 | G39: 1497.821
A40: Other non-operating assets | E40: 172.093 | F40: 150.325 | G40: 157.693
A41: Goodwill | E41: 481.235 | F41: 485.452 | G41: 491.316
A42: Other long-term assets for operation purpose | E42: 260.079 | F42: 40.55 | G42: 36.195
A43: Total Assets | E43: =SUM(E37:E42) -> 5416.233 | F43: =SUM(F37:F42) -> 5680.616 | G43: =SUM(G37:G42) -> 5611.874
A45: Liabilities
A46: Accounts Payable | E46: 254.116 | F46: 254.871 | G46: 260.791
A47: Note Payable | E47: 135 | F47: 35 | G47: 0
...

Sheet Cost of Capital
A1: AIRTHREAD CONNECTIONS
A3: WACC
A4: WD | C4: 0.3
A5: WE | C5: =1-C4 -> 0.7
A6: D/E | C6: =C4/C5 -> 0.42857143
A7: Equity beta | C7: 1.0252559
A8: Cost of equity | C8: =C17+C7*C16 -> 0.093762796
A9: Cost of Debt | C9: 0.055
A10: WACC | C10: =C4*C9*(1-C15)+C5*C8 -> 0.075533957
A14: Market Assumptions:
A15: Marginal Tax Rate | C15: 0.4
A16: Market Risk Premium | C16: 0.05
A17: Risk-Free Rate | C17: 0.0425

Sheet Near Term FCFF
A1: AIRTHREAD CONNECTIONS | Q1: =$C$16 -> 0
A3: All numbers excep figures at per share level are in millions
A5: FCFF
E6: 2008 | F6: =E6+1 -> 2009 | G6: =F6+1 -> 2010 | H6: =G6+1 -> 2011 | I6: =H6+1 -> 2012
A7: EBIT*(1-Tc) | E7: =E27 -> 243.54665 | F7: =F27 -> 277.64318 | G7: =G27 -> 334.55929 | H7: =H27 -> 387.09887 | I7: =I27 -> 434.6153
A8: Plus: Dep & Amort. | E8: =E24 -> 705.22932 | F8: =F24 -> 803.96142 | G8: =G24 -> 867.43875 | H8: =H24 -> 922.37654 | I8: =I24 -> 952.91038
A9: Less: Change in Net Working Capital | E9: =E56 -> 57.38218 | F9: =F56 -> 55.003505 | G9: =G56 -> 55.985711 | H9: =H56 -> 50.38714 | I9: =I56 -> 38.798097
A10: Less: Capital Expenditures | E10: =E71 -> 631.27447 | F10: =F71 -> 719.65289 | G10: =G71 -> 867.43875 | H10: =H71 -> 970.08567 | I10: =I71 -> 1055.0079
A11: FCFF | E11: =E7+E8-E9-E10 -> 260.11932 | F11: =F7+F8-F9-F10 -> 306.94821 | G11: =G7+G8-G9-G10 -> 278.57358 | H11: =H7+H8-H9-H10 -> 289.0026 | I11: =I7+I8-I9-I10 -> 293.71966
A14: Income Statements
D15: Historical | E15: Pro-Forma
D16: 2007 | E16: 2008 | F16: =E16+1 -> 2009 | G16: =F16+1 -> 2010 | H16: =G16+1 -> 2011 | I16: =H16+1 -> 2012
A17: Service Revenue | D17: 3679.237 | E17: =D17*(1+E31) -> 4194.3302 | F17: =E17*(1+F31) -> 4781.5364 | G17: =F17*(1+G31) -> 5379.2285 | H17: =G17*(1+H31) -> 5917.1513 | I17: =H17*(1+I31) -> 6331.3519
A18: Equipment Revenue | D18: 267.027 | E18: =E32*E17 -> 314.77315 | F18: =F32*F17 -> 358.84139 | G18: =G32*G17 -> 403.69657 | H18: =H32*H17 -> 444.06622 | I18: =I32*I17 -> 475.15086
A19: Total Revenue | D19: =SUM(D17:D18) -> 3946.264 | E19: =SUM(E17:E18) -> 4509.1033 | F19: =SUM(F17:F18) -> 5140.3778 | G19: =SUM(G17:G18) -> 5782.925 | H19: =SUM(H17:H18) -> 6361.2175 | I19: =SUM(I17:I18) -> 6806.5027
A20: Less: System Operating Expenses | E20: =E33*E17 -> 838.86604 | F20: =F33*F17 -> 956.30728 | G20: =G33*G17 -> 1075.8457 | H20: =H33*H17 -> 1183.4303 | I20: =I33*I17 -> 1266.2704
A21: Less: Cost of Goods Sold | E21: =E34*E18 -> 755.45556 | F21: =F34*F18 -> 861.21934 | G21: =G34*G18 -> 968.87176 | H21: =H34*H18 -> 1065.7589 | I21: =I34*I18 -> 1140.3621
A22: Less: Selling, General & Administrative | E22: =E35*E19 -> 1803.6413 | F22: =F35*F19 -> 2056.1511 | G22: =G35*G19 -> 2313.17 | H22: =H35*H19 -> 2544.487 | I22: =I35*I19 -> 2722.6011
A23: EBITDA | E23: =E19-E20-E21-E22 -> 1111.1404 | F23: =F19-F20-F21-F22 -> 1266.7001 | G23: =G19-G20-G21-G22 -> 1425.0376 | H23: =H19-H20-H21-H22 -> 1567.5413 | I23: =I19-I20-I21-I22 -> 1677.2692
A24: Less: Depreciation & Amortization | E24: =E36 -> 705.22932 | F24: =F36 -> 803.96142 | G24: =G36 -> 867.43875 | H24: =H36 -> 922.37654 | I24: =I36 -> 952.91038
A25: EBIT | E25: =E23-E24 -> 405.91108 | F25: =F23-F24 -> 462.73863 | G25: =G23-G24 -> 557.59881 | H25: =H23-H24 -> 645.16478 | I25: =I23-I24 -> 724.35883
A26: Less: Taxes | E26: =E25*E37 -> 162.36443 | F26: =F25*F37 -> 185.09545 | G26: =G25*G37 -> 223.03952 | H26: =H25*H37 -> 258.06591 | I26: =I25*I37 -> 289.74353
A27: EBIT*(1-Tc) | E27: =E25-E26 -> 243.54665 | F27: =F25-F26 -> 277.64318 | G27: =G25-G26 -> 334.55929 | H27: =H25-H26 -> 387.09887 | I27: =I25-I26 -> 434.6153
A30: Income Statement Assumptions :
A31: Service Revenue Growth | E31: 0.14 | F31: 0.14 | G31: 0.125 | H31: 0.1 | I31: 0.07
A32: Equipment Revenue/Service Revenue | E32: 0.075047299 | F32: 0.075047299 | G32: 0.075047299 | H32: 0.075047299 | I32: 0.075047299
A33: System Operating Exp./Service Revenue | E33: 0.2 | F33: 0.2 | G33: 0.2 | H33: 0.2 | I33: 0.2
A34: Equipment COGS/Equipment Revenue | E34: 2.4 | F34: 2.4 | G34: 2.4 | H34: 2.4 | I34: 2.4
A35: SG&A/Total Revenue | E35: 0.4 | F35: 0.4 | G35: 0.4 | H35: 0.4 | I35: 0.4
A36: Less: Depreciation & Amortization | E36: 705.22932 | F36: 803.96142 | G36: 867.43875 | H36: 922.37654 | I36: 952.91038
A37: Tax Rate | E37: 0.4 | F37: 0.4 | G37: 0.4 | H37: 0.4 | I37: 0.4
A40: Working Capital
D41: Historical | E41: Pro-Forma
D42: 2007 | E42: 2008 | F42: =E42+1 -> 2009 | G42: =F42+1 -> 2010 | H42: =G42+1 -> 2011 | I42: =H42+1 -> 2012
A43: Current Assets
A44: Cash & Cash Equivalents | D44: =D59*D19 -> 220.885 | E44: =E59*E19 -> 252.38891 | F44: =F59*F19 -> 287.72336 | G44: =G59*G19 -> 323.68878 | H44: =H59*H19 -> 356.05766 | I44: =I59*I19 -> 380.9817
A45: Account Receivable | D45: 435.497 | E45: =E60*E19 -> 521.89513 | F45: =F60*F19 -> 594.96044 | G45: =G60*G19 -> 669.3305 | H45: =H60*H19 -> 736.26355 | I45: =I60*I19 -> 787.802
A46: Inventory | D46: 100.99 | E46: =E61*E18 -> 134.96792 | F46: =F61*F18 -> 153.86343 | G46: =G61*G18 -> 173.09635 | H46: =H61*H18 -> 190.40599 | I46: =I61*I18 -> 203.73441
A47: Prepaid Expenses | D47: 41.588 | E47: =E62*SUM(E20:E22) -> 46.914828 | F47: =F62*SUM(F20:F22) -> 53.482904 | G47: =G62*SUM(G20:G22) -> 60.168267 | H47: =H62*SUM(H20:H22) -> 66.185093 | I47: =I62*SUM(I20:I22) -> 70.81805
A48: Total Current Assets | D48: =SUM(D44:D47) -> 798.96 | E48: =SUM(E44:E47) -> 956.16679 | F48: =SUM(F44:F47) -> 1090.0301 | G48: =SUM(G44:G47) -> 1226.2839 | H48: =SUM(H44:H47) -> 1348.9123 | I48: =SUM(I44:I47) -> 1443.3362
...

Sheet Terminal Value
A1: AIRTHREAD CONNECTIONS
A3: Perpeptual Growth Model
A4: Long-Term Growth Rate: | D4: 2012
A5: Historical Average ROC | D5: 0.10470294
A6: Historical Average NRR | D6: 0.28732837
A7: Est. Long-term EBIT Growth Rate | D7: =D5*D6 -> 0.030084125
A9: Terminal Value using perpeptual growth model
A10: FCFF2012 | D10: ='Near Term FCFF'!I11 -> 293.71966
A11: g | D11: =D7 -> 0.030084125
A12: WACC | D12: ='Cost of Capital'!C10 -> 0.075533957
A13: TV @ 2012 | D13: =D10*(1+D11)/(D12-D11) -> 6656.9213

Sheet AirThread Valuation
A1: AIRTHREAD CONNECTIONS
A3: All numbers excep figures at per share level are in millions
A5: Valuation of Operating Assets
A6: Period | D6: 0 | E6: 1 | F6: 2 | G6: 3 | H6: 4 | I6: 5
A7: Year | D7: 2007 | E7: 2008 | F7: =E7+1 -> 2009 | G7: =F7+1 -> 2010 | H7: =G7+1 -> 2011 | I7: =H7+1 -> 2012
A8: FCFF | E8: ='Near Term FCFF'!E11 -> 260.11932 | F8: ='Near Term FCFF'!F11 -> 306.94821 | G8: ='Near Term FCFF'!G11 -> 278.57358 | H8: ='Near Term FCFF'!H11 -> 289.0026 | I8: ='Near Term FCFF'!I11 -> 293.71966
A9: TV @ 2012 | I9: ='Terminal Value'!D13 -> 6656.9213
A10: WACC | B10: ='Cost of Capital'!C10 -> 0.075533957
A11: PV of Near Term FCFFs | B11: =NPV(B10,E8:I8) -> 1151.1684
A12: PV of Terminal Value | B12: =I9/(1+B10)^5 -> 4625.4372
A13: Value of Total Assets | B13: =SUM(B11:B12) -> 5776.6055
A18: Valuation of AirThread
A19: Value of Total Assets (or "Total Firm Value") | B19: =B13 -> 5776.6055
A20: Less: MV of Debt | B20: ='Target historical Info'!G47+'Target historical Info'!G50 -> 1002.293
A21: Less: MV of Other LT Liabilities | B21: ='Target historical Info'!G51 -> 765.786
A22: MV of Equity | B22: =B19-B20-B21 -> 4008.5265
A25: Valuation of AirThread's Equity | B25: =B22 -> 4008.5265
A26: Value Per Share | B26: =B25/'Target historical Info'!G24 -> 40.085265
